
C:\Users\umang\Desktop\pythonWorkshop\project>flask\Scripts\activate

(flask) C:\Users\umang\Desktop\pythonWorkshop\project>python app.py
Traceback (most recent call last):
  File "app.py", line 1, in <module>
    from app import app_api, db
  File "C:\Users\umang\Desktop\pythonWorkshop\project\app\__init__.py", line 1, in <module>
    from flask import Flask
  File "C:\Users\umang\Desktop\pythonWorkshop\myProj\flask\lib\site-packages\flask\__init__.py", line 19, in <module>
    from jinja2 import Markup, escape
  File "C:\Users\umang\Desktop\pythonWorkshop\myProj\flask\lib\site-packages\jinja2\__init__.py", line 33, in <module>
    from jinja2.environment import Environment, Template
  File "C:\Users\umang\Desktop\pythonWorkshop\myProj\flask\lib\site-packages\jinja2\environment.py", line 21, in <module>
    from jinja2.parser import Parser
  File "C:\Users\umang\Desktop\pythonWorkshop\myProj\flask\lib\site-packages\jinja2\parser.py", line 10, in <module>
    """
KeyboardInterrupt

(flask) C:\Users\umang\Desktop\pythonWorkshop\project>python app.py createdb

(flask) C:\Users\umang\Desktop\pythonWorkshop\project>
(flask) C:\Users\umang\Desktop\pythonWorkshop\project>python app.py createdb

(flask) C:\Users\umang\Desktop\pythonWorkshop\project>python
Python 2.7.11 (v2.7.11:6d1b6a68f775, Dec  5 2015, 20:40:30) [MSC v.1500 64 bit (AMD64)] on win32
Type "help", "copyright", "credits" or "license" for more information.
>>> from app import app_api
>>> from app import app_api^X
Exception KeyboardInterrupt in <module 'threading' from 'C:\Python27\Lib\threading.pyc'> ignored

(flask) C:\Users\umang\Desktop\pythonWorkshop\project>python app.py shell

>>> db
<SQLAlchemy engine='sqlite:///C:\\Users\\umang\\Desktop\\pythonWorkshop\\project\\app.db'>
>>> app_api
Traceback (most recent call last):
  File "<console>", line 1, in <module>
NameError: name 'app_api' is not defined
>>> app
<Flask 'app'>
>>> a = User('subham')
>>> db.session.add(a)
>>> db.session.commit()
>>> a.id
1
>>> a.name
u'subham'
>>> exit()

(flask) C:\Users\umang\Desktop\pythonWorkshop\project>python app.py createdb

(flask) C:\Users\umang\Desktop\pythonWorkshop\project>python app.py shell

>>> u = User('subham')
>>> db.session.add(u)
>>> db.session.commit()
>>> u.id
1
>>> exit()

(flask) C:\Users\umang\Desktop\pythonWorkshop\project>python app.py shell

>>> u  =User.query.all()
>>> u
[<app.schema.User object at 0x0000000003C91CF8>]
>>> u  =User.query.first()
>>> u
<app.schema.User object at 0x0000000003C91CF8>
>>> u = User.query.get(1)
>>> u
<app.schema.User object at 0x0000000003C91CF8>
>>> u = User.query.filter_by(name='subham').first()
>>> u
<app.schema.User object at 0x0000000003C91CF8>
>>> u = User.query.filter_by(name='subham').all()
>>> u
[<app.schema.User object at 0x0000000003C91CF8>]
>>> u = User.query.filter_by(name='su').all()
>>> u
[]
>>> u = User.query.filter_by(name='subham').first()
>>> u.id
1
>>> t = Todo('go to market', u.id)
>>> db.session.add(t)
>>> db.session.commit()
>>> t.id
1
>>> t.item
u'go to market'
>>> t.user_id
1
>>> t = Todo('g', u.id)
>>> db.session.add(t)
>>> db.session.commit()
>>> todos = Todo.query.filter_by(user_id=u.id).all()
>>> todos
[<app.schema.Todo object at 0x0000000003CBA2B0>, <app.schema.Todo object at 0x000000000305C358>]
>>> todos = Todo.query.filter_by(user_id=1).all()
>>> todos
[<app.schema.Todo object at 0x0000000003CBA2B0>, <app.schema.Todo object at 0x000000000305C358>]
>>> exit()

(flask) C:\Users\umang\Desktop\pythonWorkshop\project>python app.py createdb

(flask) C:\Users\umang\Desktop\pythonWorkshop\project>python app.py
usage: app.py [-?] {shell,createdb,dropall,runserver} ...

positional arguments:
  {shell,createdb,dropall,runserver}
    shell               Runs a Python shell inside Flask application context.
    createdb
    dropall
    runserver           Runs the Flask development server i.e. app.run()

optional arguments:
  -?, --help            show this help message and exit

(flask) C:\Users\umang\Desktop\pythonWorkshop\project>python app.py runserver
 * Restarting with stat
 * Debugger is active!
 * Debugger pin code: 282-295-212
 * Running on http://127.0.0.1:5000/ (Press CTRL+C to quit)

(flask) C:\Users\umang\Desktop\pythonWorkshop\project>python app.py runserver
 * Restarting with stat
 * Debugger is active!
 * Debugger pin code: 282-295-212
 * Running on http://127.0.0.1:5000/ (Press CTRL+C to quit)

(flask) C:\Users\umang\Desktop\pythonWorkshop\project>python app.py runserver -b 0.0.0.0
usage: app.py [-?] {shell,createdb,dropall,runserver} ...
app.py: error: too many arguments

(flask) C:\Users\umang\Desktop\pythonWorkshop\project>python app.py runserver -w 0.0.0.0
usage: app.py [-?] {shell,createdb,dropall,runserver} ...
app.py: error: too many arguments

(flask) C:\Users\umang\Desktop\pythonWorkshop\project>python app.py runserver -o 0.0.0.0
usage: app.py [-?] {shell,createdb,dropall,runserver} ...
app.py: error: too many arguments

(flask) C:\Users\umang\Desktop\pythonWorkshop\project>python app.py runserver -d 0.0.0.0
usage: app.py [-?] {shell,createdb,dropall,runserver} ...
app.py: error: too many arguments

(flask) C:\Users\umang\Desktop\pythonWorkshop\project>python app.py runserver
 * Restarting with stat
 * Debugger is active!
 * Debugger pin code: 282-295-212
 * Running on http://127.0.0.1:5000/ (Press CTRL+C to quit)
127.0.0.1 - - [20/Apr/2016 17:49:36] "POST /getid HTTP/1.1" 500 -
----------------------------------------
Exception happened during processing of request from ('127.0.0.1', 7419)
Traceback (most recent call last):
  File "C:\Python27\Lib\SocketServer.py", line 295, in _handle_request_noblock
    self.process_request(request, client_address)
  File "C:\Python27\Lib\SocketServer.py", line 321, in process_request
    self.finish_request(request, client_address)
  File "C:\Python27\Lib\SocketServer.py", line 334, in finish_request
    self.RequestHandlerClass(request, client_address, self)
  File "C:\Python27\Lib\SocketServer.py", line 657, in __init__
    self.finish()
  File "C:\Python27\Lib\SocketServer.py", line 716, in finish
    self.wfile.close()
  File "C:\Python27\Lib\socket.py", line 283, in close
    self.flush()
  File "C:\Python27\Lib\socket.py", line 307, in flush
    self._sock.sendall(view[write_offset:write_offset+buffer_size])
error: [Errno 10053] An established connection was aborted by the software in your host machine
----------------------------------------
127.0.0.1 - - [20/Apr/2016 17:52:58] "GET /getid HTTP/1.1" 405 -
----------------------------------------
Exception happened during processing of request from ('127.0.0.1', 7454)
Traceback (most recent call last):
  File "C:\Python27\Lib\SocketServer.py", line 295, in _handle_request_noblock
    self.process_request(request, client_address)
  File "C:\Python27\Lib\SocketServer.py", line 321, in process_request
    self.finish_request(request, client_address)
  File "C:\Python27\Lib\SocketServer.py", line 334, in finish_request
    self.RequestHandlerClass(request, client_address, self)
  File "C:\Python27\Lib\SocketServer.py", line 657, in __init__
    self.finish()
  File "C:\Python27\Lib\SocketServer.py", line 716, in finish
    self.wfile.close()
  File "C:\Python27\Lib\socket.py", line 283, in close
    self.flush()
  File "C:\Python27\Lib\socket.py", line 307, in flush
    self._sock.sendall(view[write_offset:write_offset+buffer_size])
error: [Errno 10053] An established connection was aborted by the software in your host machine
----------------------------------------
127.0.0.1 - - [20/Apr/2016 17:52:58] "GET /getid HTTP/1.1" 405 -
----------------------------------------
Exception happened during processing of request from ('127.0.0.1', 7485)
Traceback (most recent call last):
  File "C:\Python27\Lib\SocketServer.py", line 295, in _handle_request_noblock
    self.process_request(request, client_address)
  File "C:\Python27\Lib\SocketServer.py", line 321, in process_request
    self.finish_request(request, client_address)
  File "C:\Python27\Lib\SocketServer.py", line 334, in finish_request
    self.RequestHandlerClass(request, client_address, self)
  File "C:\Python27\Lib\SocketServer.py", line 657, in __init__
    self.finish()
  File "C:\Python27\Lib\SocketServer.py", line 716, in finish
    self.wfile.close()
  File "C:\Python27\Lib\socket.py", line 283, in close
    self.flush()
  File "C:\Python27\Lib\socket.py", line 307, in flush
    self._sock.sendall(view[write_offset:write_offset+buffer_size])
error: [Errno 10053] An established connection was aborted by the software in your host machine
----------------------------------------
127.0.0.1 - - [20/Apr/2016 17:52:58] "GET /getid HTTP/1.1" 405 -
----------------------------------------
Exception happened during processing of request from ('127.0.0.1', 7522)
Traceback (most recent call last):
  File "C:\Python27\Lib\SocketServer.py", line 295, in _handle_request_noblock
    self.process_request(request, client_address)
  File "C:\Python27\Lib\SocketServer.py", line 321, in process_request
    self.finish_request(request, client_address)
  File "C:\Python27\Lib\SocketServer.py", line 334, in finish_request
    self.RequestHandlerClass(request, client_address, self)
  File "C:\Python27\Lib\SocketServer.py", line 657, in __init__
    self.finish()
  File "C:\Python27\Lib\SocketServer.py", line 716, in finish
    self.wfile.close()
  File "C:\Python27\Lib\socket.py", line 283, in close
    self.flush()
  File "C:\Python27\Lib\socket.py", line 307, in flush
    self._sock.sendall(view[write_offset:write_offset+buffer_size])
error: [Errno 10053] An established connection was aborted by the software in your host machine
----------------------------------------
127.0.0.1 - - [20/Apr/2016 17:52:58] "GET /getid HTTP/1.1" 405 -
127.0.0.1 - - [20/Apr/2016 17:52:58] "POST /getid HTTP/1.1" 500 -
Traceback (most recent call last):
  File "C:\Users\umang\Desktop\pythonWorkshop\myProj\flask\lib\site-packages\flask\app.py", line 1836, in __call__
    return self.wsgi_app(environ, start_response)
  File "C:\Users\umang\Desktop\pythonWorkshop\myProj\flask\lib\site-packages\flask\app.py", line 1820, in wsgi_app
    response = self.make_response(self.handle_exception(e))
  File "C:\Users\umang\Desktop\pythonWorkshop\myProj\flask\lib\site-packages\flask\app.py", line 1403, in handle_exception
    reraise(exc_type, exc_value, tb)
  File "C:\Users\umang\Desktop\pythonWorkshop\myProj\flask\lib\site-packages\flask\app.py", line 1817, in wsgi_app
    response = self.full_dispatch_request()
  File "C:\Users\umang\Desktop\pythonWorkshop\myProj\flask\lib\site-packages\flask\app.py", line 1477, in full_dispatch_request
    rv = self.handle_user_exception(e)
  File "C:\Users\umang\Desktop\pythonWorkshop\myProj\flask\lib\site-packages\flask\app.py", line 1381, in handle_user_exception
    reraise(exc_type, exc_value, tb)
  File "C:\Users\umang\Desktop\pythonWorkshop\myProj\flask\lib\site-packages\flask\app.py", line 1475, in full_dispatch_request
    rv = self.dispatch_request()
  File "C:\Users\umang\Desktop\pythonWorkshop\myProj\flask\lib\site-packages\flask\app.py", line 1461, in dispatch_request
    return self.view_functions[rule.endpoint](**req.view_args)
  File "C:\Users\umang\Desktop\pythonWorkshop\project\app\apis.py", line 12, in get_id
    db.session.add(user)
NameError: global name 'db' is not defined
127.0.0.1 - - [20/Apr/2016 17:52:59] "GET /favicon.ico HTTP/1.1" 404 -
 * Detected change in 'C:\\Users\\umang\\Desktop\\pythonWorkshop\\project\\app\\apis.py', reloading
 * Restarting with stat
 * Debugger is active!
 * Debugger pin code: 282-295-212
 * Running on http://127.0.0.1:5000/ (Press CTRL+C to quit)
127.0.0.1 - - [20/Apr/2016 17:53:19] "GET /getid HTTP/1.1" 405 -
127.0.0.1 - - [20/Apr/2016 17:53:29] "POST /getid HTTP/1.1" 200 -
 * Detected change in 'C:\\Users\\umang\\Desktop\\pythonWorkshop\\project\\app\\apis.py', reloading
 * Restarting with stat
Traceback (most recent call last):
  File "app.py", line 1, in <module>
    from app import app_api, db
  File "C:\Users\umang\Desktop\pythonWorkshop\project\app\__init__.py", line 8, in <module>
    from app import apis
  File "C:\Users\umang\Desktop\pythonWorkshop\project\app\apis.py", line 30
    db.session.add(todo)
    ^
IndentationError: unexpected indent

(flask) C:\Users\umang\Desktop\pythonWorkshop\project>python app.py runserver
Traceback (most recent call last):
  File "app.py", line 1, in <module>
    from app import app_api, db
  File "C:\Users\umang\Desktop\pythonWorkshop\project\app\__init__.py", line 8, in <module>
    from app import apis
  File "C:\Users\umang\Desktop\pythonWorkshop\project\app\apis.py", line 31
    db.session.add(todo)
    ^
IndentationError: unexpected indent

(flask) C:\Users\umang\Desktop\pythonWorkshop\project>python app.py runserver
 * Restarting with stat
 * Debugger is active!
 * Debugger pin code: 282-295-212
 * Running on http://127.0.0.1:5000/ (Press CTRL+C to quit)
127.0.0.1 - - [20/Apr/2016 18:01:21] "POST /todos HTTP/1.1" 200 -
127.0.0.1 - - [20/Apr/2016 18:01:30] "POST /todos HTTP/1.1" 404 -